Workbook

Sheet 相関係数
B1: 終値 | C1: 終値
A2: 45495 | B2: 200 | C2: 100
A3: 45492 | B3: 196 | C3: 145 | D3: 3か月相関係数
A4: 45491 | B4: 200 | C4: 125
A5: 45490 | B5: 204 | C5: 129 | D5: =CORREL(B2:B65,C2:C65) -> -0.094811181
A6: 45489 | B6: 203 | C6: 102
A7: 45485 | B7: 205 | C7: 93
A8: 45484 | B8: 203 | C8: 95 | D8: ２年相関係数
A9: 45483 | B9: 203 | C9: 88
A10: 45482 | B10: 209 | C10: 87 | D10: {=CORREL(B2:B609,C2:C609)} -> 0.66249549
A11: 45481 | B11: 211 | C11: 80
A12: 45478 | B12: 212 | C12: 80
A13: 45477 | B13: 209 | C13: 80
A14: 45476 | B14: 213 | C14: 85
A15: 45475 | B15: 206 | C15: 90
A16: 45474 | B16: 206 | C16: 100
A17: 45471 | B17: 217 | C17: 99
A18: 45470 | B18: 220 | C18: 103
A19: 45469 | B19: 224 | C19: 100
A20: 45468 | B20: 230 | C20: 95
A21: 45467 | B21: 231 | C21: 95
A22: 45464 | B22: 226 | C22: 87
... A494: 44762 | B494: 183 | C494: 53

Sheet 長期
A1: 日付 | B1: =F1 -> 終値 | C1: =G1 -> 終値 | D1: サヤ | F1: ='相関係数'!B1 -> 終値 | G1: ='相関係数'!C1 -> 終値 | H1: 倍率 | I1: 1 | J1: 1 | T1: 日付 | U1: サヤ | V1: =F1 -> 終値 | W1: =G1 -> 終値
A2: =E2 -> 45495 | B2: =F2*$I$1 -> 200 | C2: =G2*$J$1 -> 100 | D2: =B2-C2 -> 100 | E2: ='相関係数'!A2 -> 45495 | F2: ='相関係数'!B2 -> 200 | G2: ='相関係数'!C2 -> 100 | J2: 3 | Q2: 長期相関係数 | R2: =IF(ISERROR(CORREL(W2:W1274,V2:V1274)),"",CORREL(W2:W1274,V2:V1274)) -> 0.66249549 | T2: =A494 -> 44762 | U2: =D494 -> 130 | V2: =B494 -> 183 | W2: =C494 -> 53
A3: =E3 -> 45492 | B3: =F3*$I$1 -> 196 | C3: =G3*$J$1 -> 145 | D3: =B3-C3 -> 51 | E3: ='相関係数'!A3 -> 45492 | F3: ='相関係数'!B3 -> 196 | G3: ='相関係数'!C3 -> 145 | Q3: サヤ平均 | R3: =IF(ISERROR(AVERAGE(U2:U1274)),"",AVERAGE(U2:U1274)) -> 127.01623 | T3: =A493 -> 44763 | U3: =D493 -> 146 | V3: =B493 -> 200 | W3: =C493 -> 54
A4: =E4 -> 45491 | B4: =F4*$I$1 -> 200 | C4: =G4*$J$1 -> 125 | D4: =B4-C4 -> 75 | E4: ='相関係数'!A4 -> 45491 | F4: ='相関係数'!B4 -> 200 | G4: ='相関係数'!C4 -> 125 | Q4: 標準偏差(σ) | R4: =IF(ISERROR(STDEV(U2:U1274)),"",STDEV(U2:U1274)) -> 23.71142 | T4: =A492 -> 44764 | U4: =D492 -> 143 | V4: =B492 -> 197 | W4: =C492 -> 54
A5: =E5 -> 45490 | B5: =F5*$I$1 -> 204 | C5: =G5*$J$1 -> 129 | D5: =B5-C5 -> 75 | E5: ='相関係数'!A5 -> 45490 | F5: ='相関係数'!B5 -> 204 | G5: ='相関係数'!C5 -> 129 | Q5: ＋2σ | R5: =IF(ISERROR(R3+R4*2),"",R3+R4*2) -> 174.43907 | T5: =A491 -> 44767 | U5: =D491 -> 138 | V5: =B491 -> 191 | W5: =C491 -> 53
A6: =E6 -> 45489 | B6: =F6*$I$1 -> 203 | C6: =G6*$J$1 -> 102 | D6: =B6-C6 -> 101 | E6: ='相関係数'!A6 -> 45489 | F6: ='相関係数'!B6 -> 203 | G6: ='相関係数'!C6 -> 102 | Q6: ＋1σ | R6: =IF(ISERROR(R3+R4),"",R3+R4) -> 150.72765 | T6: =A490 -> 44768 | U6: =D490 -> 141 | V6: =B490 -> 195 | W6: =C490 -> 54
A7: =E7 -> 45485 | B7: =F7*$I$1 -> 205 | C7: =G7*$J$1 -> 93 | D7: =B7-C7 -> 112 | E7: ='相関係数'!A7 -> 45485 | F7: ='相関係数'!B7 -> 205 | G7: ='相関係数'!C7 -> 93 | Q7: −1σ | R7: =IF(ISERROR(R3-R4),"",R3-R4) -> 103.30481 | T7: =A489 -> 44769 | U7: =D489 -> 138 | V7: =B489 -> 192 | W7: =C489 -> 54
A8: =E8 -> 45484 | B8: =F8*$I$1 -> 203 | C8: =G8*$J$1 -> 95 | D8: =B8-C8 -> 108 | E8: ='相関係数'!A8 -> 45484 | F8: ='相関係数'!B8 -> 203 | G8: ='相関係数'!C8 -> 95 | Q8: −2σ | R8: =IF(ISERROR(R3-R4*2),"",R3-R4*2) -> 79.593387 | T8: =A488 -> 44770 | U8: =D488 -> 137 | V8: =B488 -> 191 | W8: =C488 -> 54
A9: =E9 -> 45483 | B9: =F9*$I$1 -> 203 | C9: =G9*$J$1 -> 88 | D9: =B9-C9 -> 115 | E9: ='相関係数'!A9 -> 45483 | F9: ='相関係数'!B9 -> 203 | G9: ='相関係数'!C9 -> 88 | T9: =A487 -> 44771 | U9: =D487 -> 140 | V9: =B487 -> 193 | W9: =C487 -> 53
A10: =E10 -> 45482 | B10: =F10*$I$1 -> 209 | C10: =G10*$J$1 -> 87 | D10: =B10-C10 -> 122 | E10: ='相関係数'!A10 -> 45482 | F10: ='相関係数'!B10 -> 209 | G10: ='相関係数'!C10 -> 87 | T10: =A486 -> 44774 | U10: =D486 -> 143 | V10: =B486 -> 196 | W10: =C486 -> 53
A11: =E11 -> 45481 | B11: =F11*$I$1 -> 211 | C11: =G11*$J$1 -> 80 | D11: =B11-C11 -> 131 | E11: ='相関係数'!A11 -> 45481 | F11: ='相関係数'!B11 -> 211 | G11: ='相関係数'!C11 -> 80 | T11: =A485 -> 44775 | U11: =D485 -> 143 | V11: =B485 -> 196 | W11: =C485 -> 53
A12: =E12 -> 45478 | B12: =F12*$I$1 -> 212 | C12: =G12*$J$1 -> 80 | D12: =B12-C12 -> 132 | E12: ='相関係数'!A12 -> 45478 | F12: ='相関係数'!B12 -> 212 | G12: ='相関係数'!C12 -> 80 | T12: =A484 -> 44776 | U12: =D484 -> 143 | V12: =B484 -> 196 | W12: =C484 -> 53
A13: =E13 -> 45477 | B13: =F13*$I$1 -> 209 | C13: =G13*$J$1 -> 80 | D13: =B13-C13 -> 129 | E13: ='相関係数'!A13 -> 45477 | F13: ='相関係数'!B13 -> 209 | G13: ='相関係数'!C13 -> 80 | T13: =A483 -> 44777 | U13: =D483 -> 145 | V13: =B483 -> 198 | W13: =C483 -> 53
A14: =E14 -> 45476 | B14: =F14*$I$1 -> 213 | C14: =G14*$J$1 -> 85 | D14: =B14-C14 -> 128 | E14: ='相関係数'!A14 -> 45476 | F14: ='相関係数'!B14 -> 213 | G14: ='相関係数'!C14 -> 85 | T14: =A482 -> 44778 | U14: =D482 -> 144 | V14: =B482 -> 196 | W14: =C482 -> 52
A15: =E15 -> 45475 | B15: =F15*$I$1 -> 206 | C15: =G15*$J$1 -> 90 | D15: =B15-C15 -> 116 | E15: ='相関係数'!A15 -> 45475 | F15: ='相関係数'!B15 -> 206 | G15: ='相関係数'!C15 -> 90 | T15: =A481 -> 44781 | U15: =D481 -> 131 | V15: =B481 -> 181 | W15: =C481 -> 50
A16: =E16 -> 45474 | B16: =F16*$I$1 -> 206 | C16: =G16*$J$1 -> 100 | D16: =B16-C16 -> 106 | E16: ='相関係数'!A16 -> 45474 | F16: ='相関係数'!B16 -> 206 | G16: ='相関係数'!C16 -> 100 | T16: =A480 -> 44782 | U16: =D480 -> 129 | V16: =B480 -> 181 | W16: =C480 -> 52
A17: =E17 -> 45471 | B17: =F17*$I$1 -> 217 | C17: =G17*$J$1 -> 99 | D17: =B17-C17 -> 118 | E17: ='相関係数'!A17 -> 45471 | F17: ='相関係数'!B17 -> 217 | G17: ='相関係数'!C17 -> 99 | T17: =A479 -> 44783 | U17: =D479 -> 128 | V17: =B479 -> 179 | W17: =C479 -> 51
A18: =E18 -> 45470 | B18: =F18*$I$1 -> 220 | C18: =G18*$J$1 -> 103 | D18: =B18-C18 -> 117 | E18: ='相関係数'!A18 -> 45470 | F18: ='相関係数'!B18 -> 220 | G18: ='相関係数'!C18 -> 103 | T18: =A478 -> 44785 | U18: =D478 -> 128 | V18: =B478 -> 180 | W18: =C478 -> 52
A19: =E19 -> 45469 | B19: =F19*$I$1 -> 224 | C19: =G19*$J$1 -> 100 | D19: =B19-C19 -> 124 | E19: ='相関係数'!A19 -> 45469 | F19: ='相関係数'!B19 -> 224 | G19: ='相関係数'!C19 -> 100 | T19: =A477 -> 44788 | U19: =D477 -> 130 | V19: =B477 -> 181 | W19: =C477 -> 51
A20: =E20 -> 45468 | B20: =F20*$I$1 -> 230 | C20: =G20*$J$1 -> 95 | D20: =B20-C20 -> 135 | E20: ='相関係数'!A20 -> 45468 | F20: ='相関係数'!B20 -> 230 | G20: ='相関係数'!C20 -> 95 | T20: =A476 -> 44789 | U20: =D476 -> 131 | V20: =B476 -> 183 | W20: =C476 -> 52
A21: =E21 -> 45467 | B21: =F21*$I$1 -> 231 | C21: =G21*$J$1 -> 95 | D21: =B21-C21 -> 136 | E21: ='相関係数'!A21 -> 45467 | F21: ='相関係数'!B21 -> 231 | G21: ='相関係数'!C21 -> 95 | T21: =A475 -> 44790 | U21: =D475 -> 132 | V21: =B475 -> 183 | W21: =C475 -> 51
A22: =E22 -> 45464 | B22: =F22*$I$1 -> 226 | C22: =G22*$J$1 -> 87 | D22: =B22-C22 -> 139 | E22: ='相関係数'!A22 -> 45464 | F22: ='相関係数'!B22 -> 226 | G22: ='相関係数'!C22 -> 87 | T22: =A474 -> 44791 | U22: =D474 -> 128 | V22: =B474 -> 184 | W22: =C474 -> 56
A23: =E23 -> 45463 | B23: =F23*$I$1 -> 220 | C23: =G23*$J$1 -> 81 | D23: =B23-C23 -> 139 | E23: ='相関係数'!A23 -> 45463 | F23: ='相関係数'!B23 -> 220 | G23: ='相関係数'!C23 -> 81 | T23: =A473 -> 44792 | U23: =D473 -> 130 | V23: =B473 -> 185 | W23: =C473 -> 55
A24: =E24 -> 45462 | B24: =F24*$I$1 -> 222 | C24: =G24*$J$1 -> 83 | D24: =B24-C24 -> 139 | E24: ='相関係数'!A24 -> 45462 | F24: ='相関係数'!B24 -> 222 | G24: ='相関係数'!C24 -> 83 | T24: =A472 -> 44795 | U24: =D472 -> 135 | V24: =B472 -> 182 | W24: =C472 -> 47
A25: =E25 -> 45461 | B25: =F25*$I$1 -> 219 | C25: =G25*$J$1 -> 84 | D25: =B25-C25 -> 135 | E25: ='相関係数'!A25 -> 45461 | F25: ='相関係数'!B25 -> 219 | G25: ='相関係数'!C25 -> 84 | T25: =A471 -> 44796 | U25: =D471 -> 138 | V25: =B471 -> 183 | W25: =C471 -> 45
A26: =E26 -> 45460 | B26: =F26*$I$1 -> 218 | C26: =G26*$J$1 -> 89 | D26: =B26-C26 -> 129 | E26: ='相関係数'!A26 -> 45460 | F26: ='相関係数'!B26 -> 218 | G26: ='相関係数'!C26 -> 89 | T26: =A470 -> 44797 | U26: =D470 -> 138 | V26: =B470 -> 181 | W26: =C470 -> 43
A27: =E27 -> 45457 | B27: =F27*$I$1 -> 221 | C27: =G27*$J$1 -> 90 | D27: =B27-C27 -> 131 | E27: ='相関係数'!A27 -> 45457 | F27: ='相関係数'!B27 -> 221 | G27: ='相関係数'!C27 -> 90 | T27: =A469 -> 44798 | U27: =D469 -> 140 | V27: =B469 -> 182 | W27: =C469 -> 42
A28: =E28 -> 45456 | B28: =F28*$I$1 -> 230 | C28: =G28*$J$1 -> 95 | D28: =B28-C28 -> 135 | E28: ='相関係数'!A28 -> 45456 | F28: ='相関係数'!B28 -> 230 | G28: ='相関係数'!C28 -> 95 | T28: =A468 -> 44799 | U28: =D468 -> 140 | V28: =B468 -> 182 | W28: =C468 -> 42
A29: =E29 -> 45455 | B29: =F29*$I$1 -> 219 | C29: =G29*$J$1 -> 107 | D29: =B29-C29 -> 112 | E29: ='相関係数'!A29 -> 45455 | F29: ='相関係数'!B29 -> 219 | G29: ='相関係数'!C29 -> 107 | T29: =A467 -> 44802 | U29: =D467 -> 141 | V29: =B467 -> 183 | W29: =C467 -> 42
A30: =E30 -> 45454 | B30: =F30*$I$1 -> 216 | C30: =G30*$J$1 -> 89 | D30: =B30-C30 -> 127 | E30: ='相関係数'!A30 -> 45454 | F30: ='相関係数'!B30 -> 216 | G30: ='相関係数'!C30 -> 89 | T30: =A466 -> 44803 | U30: =D466 -> 139 | V30: =B466 -> 181 | W30: =C466 -> 42
A31: =E31 -> 45453 | B31: =F31*$I$1 -> 216 | C31: =G31*$J$1 -> 81 | D31: =B31-C31 -> 135 | E31: ='相関係数'!A31 -> 45453 | F31: ='相関係数'!B31 -> 216 | G31: ='相関係数'!C31 -> 81 | T31: =A465 -> 44804 | U31: =D465 -> 142 | V31: =B465 -> 185 | W31: =C465 -> 43
A32: =E32 -> 45450 | B32: =F32*$I$1 -> 226 | C32: =G32*$J$1 -> 85 | D32: =B32-C32 -> 141 | E32: ='相関係数'!A32 -> 45450 | F32: ='相関係数'!B32 -> 226 | G32: ='相関係数'!C32 -> 85 | T32: =A464 -> 44805 | U32: =D464 -> 139 | V32: =B464 -> 181 | W32: =C464 -> 42
A33: =E33 -> 45449 | B33: =F33*$I$1 -> 219 | C33: =G33*$J$1 -> 78 | D33: =B33-C33 -> 141 | E33: ='相関係数'!A33 -> 45449 | F33: ='相関係数'!B33 -> 219 | G33: ='相関係数'!C33 -> 78 | T33: =A463 -> 44806 | U33: =D463 -> 135 | V33: =B463 -> 179 | W33: =C463 -> 44
A34: =E34 -> 45448 | B34: =F34*$I$1 -> 225 | C34: =G34*$J$1 -> 84 | D34: =B34-C34 -> 141 | E34: ='相関係数'!A34 -> 45448 | F34: ='相関係数'!B34 -> 225 | G34: ='相関係数'!C34 -> 84 | T34: =A462 -> 44809 | U34: =D462 -> 136 | V34: =B462 -> 180 | W34: =C462 -> 44
A35: =E35 -> 45447 | B35: =F35*$I$1 -> 235 | C35: =G35*$J$1 -> 66 | D35: =B35-C35 -> 169 | E35: ='相関係数'!A35 -> 45447 | F35: ='相関係数'!B35 -> 235 | G35: ='相関係数'!C35 -> 66 | T35: =A461 -> 44810 | U35: =D461 -> 136 | V35: =B461 -> 180 | W35: =C461 -> 44
A36: =E36 -> 45446 | B36: =F36*$I$1 -> 234 | C36: =G36*$J$1 -> 62 | D36: =B36-C36 -> 172 | E36: ='相関係数'!A36 -> 45446 | F36: ='相関係数'!B36 -> 234 | G36: ='相関係数'!C36 -> 62 | T36: =A460 -> 44811 | U36: =D460 -> 135 | V36: =B460 -> 179 | W36: =C460 -> 44
A37: =E37 -> 45443 | B37: =F37*$I$1 -> 237 | C37: =G37*$J$1 -> 52 | D37: =B37-C37 -> 185 | E37: ='相関係数'!A37 -> 45443 | F37: ='相関係数'!B37 -> 237 | G37: ='相関係数'!C37 -> 52 | T37: =A459 -> 44812 | U37: =D459 -> 136 | V37: =B459 -> 179 | W37: =C459 -> 43
A38: =E38 -> 45442 | B38: =F38*$I$1 -> 229 | C38: =G38*$J$1 -> 55 | D38: =B38-C38 -> 174 | E38: ='相関係数'!A38 -> 45442 | F38: ='相関係数'!B38 -> 229 | G38: ='相関係数'!C38 -> 55 | T38: =A458 -> 44813 | U38: =D458 -> 126 | V38: =B458 -> 180 | W38: =C458 -> 54
A39: =E39 -> 45441 | B39: =F39*$I$1 -> 240 | C39: =G39*$J$1 -> 56 | D39: =B39-C39 -> 184 | E39: ='相関係数'!A39 -> 45441 | F39: ='相関係数'!B39 -> 240 | G39: ='相関係数'!C39 -> 56 | T39: =A457 -> 44816 | U39: =D457 -> 130 | V39: =B457 -> 182 | W39: =C457 -> 52
A40: =E40 -> 45440 | B40: =F40*$I$1 -> 262 | C40: =G40*$J$1 -> 62 | D40: =B40-C40 -> 200 | E40: ='相関係数'!A40 -> 45440 | F40: ='相関係数'!B40 -> 262 | G40: ='相関係数'!C40 -> 62 | T40: =A456 -> 44817 | U40: =D456 -> 130 | V40: =B456 -> 181 | W40: =C456 -> 51
...

Sheet 短期
A1: 日付 | B1: ='長期'!B1 -> 終値 | C1: ='長期'!C1 -> 終値 | D1: ='長期'!D1 -> サヤ | S1: 日付 | T1: サヤ | U1: ='長期'!F1 -> 終値 | V1: ='長期'!G1 -> 終値
A2: ='長期'!A2 -> 45495 | B2: ='長期'!B2 -> 200 | C2: ='長期'!C2 -> 100 | D2: ='長期'!D2 -> 100 | S2: =A65 -> 45400 | T2: =D65 -> 138 | U2: =B65 -> 166 | V2: =C65 -> 28
A3: ='長期'!A3 -> 45492 | B3: ='長期'!B3 -> 196 | C3: ='長期'!C3 -> 145 | D3: ='長期'!D3 -> 51 | S3: =A64 -> 45401 | T3: =D64 -> 140 | U3: =B64 -> 170 | V3: =C64 -> 30
A4: ='長期'!A4 -> 45491 | B4: ='長期'!B4 -> 200 | C4: ='長期'!C4 -> 125 | D4: ='長期'!D4 -> 75 | N4: 短期相関係数 | O4: =IF(ISERROR(CORREL(V2:V1301,U2:U1301)),"",CORREL(V2:V1301,U2:U1301)) -> -0.094811181 | S4: =A63 -> 45404 | T4: =D63 -> 135 | U4: =B63 -> 166 | V4: =C63 -> 31
A5: ='長期'!A5 -> 45490 | B5: ='長期'!B5 -> 204 | C5: ='長期'!C5 -> 129 | D5: ='長期'!D5 -> 75 | N5: サヤ平均 | O5: =IF(ISERROR(AVERAGE(T2:T1301)),"",AVERAGE(T2:T1301)) -> 154.01562 | S5: =A62 -> 45405 | T5: =D62 -> 134 | U5: =B62 -> 168 | V5: =C62 -> 34
A6: ='長期'!A6 -> 45489 | B6: ='長期'!B6 -> 203 | C6: ='長期'!C6 -> 102 | D6: ='長期'!D6 -> 101 | N6: 標準偏差(3か月) | O6: =IF(ISERROR(STDEV(T2:T1301)),"",STDEV(T2:T1301)) -> 44.965063 | S6: =A61 -> 45406 | T6: =D61 -> 142 | U6: =B61 -> 174 | V6: =C61 -> 32
A7: ='長期'!A7 -> 45485 | B7: ='長期'!B7 -> 205 | C7: ='長期'!C7 -> 93 | D7: ='長期'!D7 -> 112 | N7: 最新標準偏差(25日) | O7: =STDEV(D2:D26) -> 22.379529 | S7: =A60 -> 45407 | T7: =D60 -> 151 | U7: =B60 -> 179 | V7: =C60 -> 28
A8: ='長期'!A8 -> 45484 | B8: ='長期'!B8 -> 203 | C8: ='長期'!C8 -> 95 | D8: ='長期'!D8 -> 108 | N8: ＋2σ | O8: =IF(ISERROR(O5+O6*2),"",O5+O6*2) -> 243.94575 | S8: =A59 -> 45408 | T8: =D59 -> 156 | U8: =B59 -> 185 | V8: =C59 -> 29
A9: ='長期'!A9 -> 45483 | B9: ='長期'!B9 -> 203 | C9: ='長期'!C9 -> 88 | D9: ='長期'!D9 -> 115 | N9: ＋1σ | O9: =IF(ISERROR(O5+O6),"",O5+O6) -> 198.98069 | S9: =A58 -> 45412 | T9: =D58 -> 177 | U9: =B58 -> 206 | V9: =C58 -> 29
A10: ='長期'!A10 -> 45482 | B10: ='長期'!B10 -> 209 | C10: ='長期'!C10 -> 87 | D10: ='長期'!D10 -> 122 | N10: −1σ | O10: =IF(ISERROR(O5-O6),"",O5-O6) -> 109.05056 | S10: =A57 -> 45413 | T10: =D57 -> 165 | U10: =B57 -> 194 | V10: =C57 -> 29
A11: ='長期'!A11 -> 45481 | B11: ='長期'!B11 -> 211 | C11: ='長期'!C11 -> 80 | D11: ='長期'!D11 -> 131 | N11: −2σ | O11: =IF(ISERROR(O5-O6*2),"",O5-O6*2) -> 64.085499 | S11: =A56 -> 45414 | T11: =D56 -> 161 | U11: =B56 -> 189 | V11: =C56 -> 28
A12: ='長期'!A12 -> 45478 | B12: ='長期'!B12 -> 212 | C12: ='長期'!C12 -> 80 | D12: ='長期'!D12 -> 132 | S12: =A55 -> 45419 | T12: =D55 -> 210 | U12: =B55 -> 239 | V12: =C55 -> 29
A13: ='長期'!A13 -> 45477 | B13: ='長期'!B13 -> 209 | C13: ='長期'!C13 -> 80 | D13: ='長期'!D13 -> 129 | S13: =A54 -> 45420 | T13: =D54 -> 246 | U13: =B54 -> 276 | V13: =C54 -> 30
A14: ='長期'!A14 -> 45476 | B14: ='長期'!B14 -> 213 | C14: ='長期'!C14 -> 85 | D14: ='長期'!D14 -> 128 | S14: =A53 -> 45421 | T14: =D53 -> 248 | U14: =B53 -> 277 | V14: =C53 -> 29
A15: ='長期'!A15 -> 45475 | B15: ='長期'!B15 -> 206 | C15: ='長期'!C15 -> 90 | D15: ='長期'!D15 -> 116 | S15: =A52 -> 45422 | T15: =D52 -> 234 | U15: =B52 -> 264 | V15: =C52 -> 30
A16: ='長期'!A16 -> 45474 | B16: ='長期'!B16 -> 206 | C16: ='長期'!C16 -> 100 | D16: ='長期'!D16 -> 106 | S16: =A51 -> 45425 | T16: =D51 -> 225 | U16: =B51 -> 255 | V16: =C51 -> 30
A17: ='長期'!A17 -> 45471 | B17: ='長期'!B17 -> 217 | C17: ='長期'!C17 -> 99 | D17: ='長期'!D17 -> 118 | S17: =A50 -> 45426 | T17: =D50 -> 226 | U17: =B50 -> 257 | V17: =C50 -> 31
A18: ='長期'!A18 -> 45470 | B18: ='長期'!B18 -> 220 | C18: ='長期'!C18 -> 103 | D18: ='長期'!D18 -> 117 | S18: =A49 -> 45427 | T18: =D49 -> 216 | U18: =B49 -> 249 | V18: =C49 -> 33
A19: ='長期'!A19 -> 45469 | B19: ='長期'!B19 -> 224 | C19: ='長期'!C19 -> 100 | D19: ='長期'!D19 -> 124 | S19: =A48 -> 45428 | T19: =D48 -> 208 | U19: =B48 -> 243 | V19: =C48 -> 35
A20: ='長期'!A20 -> 45468 | B20: ='長期'!B20 -> 230 | C20: ='長期'!C20 -> 95 | D20: ='長期'!D20 -> 135 | S20: =A47 -> 45429 | T20: =D47 -> 217 | U20: =B47 -> 252 | V20: =C47 -> 35
A21: ='長期'!A21 -> 45467 | B21: ='長期'!B21 -> 231 | C21: ='長期'!C21 -> 95 | D21: ='長期'!D21 -> 136 | S21: =A46 -> 45432 | T21: =D46 -> 233 | U21: =B46 -> 274 | V21: =C46 -> 41
A22: ='長期'!A22 -> 45464 | B22: ='長期'!B22 -> 226 | C22: ='長期'!C22 -> 87 | D22: ='長期'!D22 -> 139 | S22: =A45 -> 45433 | T22: =D45 -> 231 | U22: =B45 -> 291 | V22: =C45 -> 60
A23: ='長期'!A23 -> 45463 | B23: ='長期'!B23 -> 220 | C23: ='長期'!C23 -> 81 | D23: ='長期'!D23 -> 139 | S23: =A44 -> 45434 | T23: =D44 -> 200 | U23: =B44 -> 290 | V23: =C44 -> 90
A24: ='長期'!A24 -> 45462 | B24: ='長期'!B24 -> 222 | C24: ='長期'!C24 -> 83 | D24: ='長期'!D24 -> 139 | S24: =A43 -> 45435 | T24: =D43 -> 205 | U24: =B43 -> 281 | V24: =C43 -> 76
A25: ='長期'!A25 -> 45461 | B25: ='長期'!B25 -> 219 | C25: ='長期'!C25 -> 84 | D25: ='長期'!D25 -> 135 | S25: =A42 -> 45436 | T25: =D42 -> 202 | U25: =B42 -> 259 | V25: =C42 -> 57
A26: ='長期'!A26 -> 45460 | B26: ='長期'!B26 -> 218 | C26: ='長期'!C26 -> 89 | D26: ='長期'!D26 -> 129 | S26: =A41 -> 45439 | T26: =D41 -> 198 | U26: =B41 -> 265 | V26: =C41 -> 67
A27: ='長期'!A27 -> 45457 | B27: ='長期'!B27 -> 221 | C27: ='長期'!C27 -> 90 | D27: ='長期'!D27 -> 131 | S27: =A40 -> 45440 | T27: =D40 -> 200 | U27: =B40 -> 262 | V27: =C40 -> 62
A28: ='長期'!A28 -> 45456 | B28: ='長期'!B28 -> 230 | C28: ='長期'!C28 -> 95 | D28: ='長期'!D28 -> 135 | S28: =A39 -> 45441 | T28: =D39 -> 184 | U28: =B39 -> 240 | V28: =C39 -> 56
A29: ='長期'!A29 -> 45455 | B29: ='長期'!B29 -> 219 | C29: ='長期'!C29 -> 107 | D29: ='長期'!D29 -> 112 | S29: =A38 -> 45442 | T29: =D38 -> 174 | U29: =B38 -> 229 | V29: =C38 -> 55
A30: ='長期'!A30 -> 45454 | B30: ='長期'!B30 -> 216 | C30: ='長期'!C30 -> 89 | D30: ='長期'!D30 -> 127 | S30: =A37 -> 45443 | T30: =D37 -> 185 | U30: =B37 -> 237 | V30: =C37 -> 52
A31: ='長期'!A31 -> 45453 | B31: ='長期'!B31 -> 216 | C31: ='長期'!C31 -> 81 | D31: ='長期'!D31 -> 135 | S31: =A36 -> 45446 | T31: =D36 -> 172 | U31: =B36 -> 234 | V31: =C36 -> 62
A32: ='長期'!A32 -> 45450 | B32: ='長期'!B32 -> 226 | C32: ='長期'!C32 -> 85 | D32: ='長期'!D32 -> 141 | S32: =A35 -> 45447 | T32: =D35 -> 169 | U32: =B35 -> 235 | V32: =C35 -> 66
A33: ='長期'!A33 -> 45449 | B33: ='長期'!B33 -> 219 | C33: ='長期'!C33 -> 78 | D33: ='長期'!D33 -> 141 | S33: =A34 -> 45448 | T33: =D34 -> 141 | U33: =B34 -> 225 | V33: =C34 -> 84
A34: ='長期'!A34 -> 45448 | B34: ='長期'!B34 -> 225 | C34: ='長期'!C34 -> 84 | D34: ='長期'!D34 -> 141 | S34: =A33 -> 45449 | T34: =D33 -> 141 | U34: =B33 -> 219 | V34: =C33 -> 78
A35: ='長期'!A35 -> 45447 | B35: ='長期'!B35 -> 235 | C35: ='長期'!C35 -> 66 | D35: ='長期'!D35 -> 169 | S35: =A32 -> 45450 | T35: =D32 -> 141 | U35: =B32 -> 226 | V35: =C32 -> 85
A36: ='長期'!A36 -> 45446 | B36: ='長期'!B36 -> 234 | C36: ='長期'!C36 -> 62 | D36: ='長期'!D36 -> 172 | S36: =A31 -> 45453 | T36: =D31 -> 135 | U36: =B31 -> 216 | V36: =C31 -> 81
A37: ='長期'!A37 -> 45443 | B37: ='長期'!B37 -> 237 | C37: ='長期'!C37 -> 52 | D37: ='長期'!D37 -> 185 | S37: =A30 -> 45454 | T37: =D30 -> 127 | U37: =B30 -> 216 | V37: =C30 -> 89
A38: ='長期'!A38 -> 45442 | B38: ='長期'!B38 -> 229 | C38: ='長期'!C38 -> 55 | D38: ='長期'!D38 -> 174 | S38: =A29 -> 45455 | T38: =D29 -> 112 | U38: =B29 -> 219 | V38: =C29 -> 107
A39: ='長期'!A39 -> 45441 | B39: ='長期'!B39 -> 240 | C39: ='長期'!C39 -> 56 | D39: ='長期'!D39 -> 184 | S39: =A28 -> 45456 | T39: =D28 -> 135 | U39: =B28 -> 230 | V39: =C28 -> 95
A40: ='長期'!A40 -> 45440 | B40: ='長期'!B40 -> 262 | C40: ='長期'!C40 -> 62 | D40: ='長期'!D40 -> 200 | S40: =A27 -> 45457 | T40: =D27 -> 131 | U40: =B27 -> 221 | V40: =C27 -> 90
...

Sheet ボリンジャーバンド
A1: =IF('長期'!A1="","",'長期'!A1) -> 日付 | B1: ＋２σ | C1: ＋σ | D1: サヤ | E1: −σ | F1: −2σ | H1: 最新標準偏差 | I1: =STDEV(D470:D494) -> 22.379529
A2: =IF('長期'!A494="","",'長期'!A494) -> 44762 | D2: ='長期'!D494 -> 130
A3: =IF('長期'!A493="","",'長期'!A493) -> 44763 | D3: ='長期'!D493 -> 146
A4: =IF('長期'!A492="","",'長期'!A492) -> 44764 | D4: ='長期'!D492 -> 143
A5: =IF('長期'!A491="","",'長期'!A491) -> 44767 | D5: ='長期'!D491 -> 138
A6: =IF('長期'!A490="","",'長期'!A490) -> 44768 | D6: ='長期'!D490 -> 141
A7: =IF('長期'!A489="","",'長期'!A489) -> 44769 | D7: ='長期'!D489 -> 138
A8: =IF('長期'!A488="","",'長期'!A488) -> 44770 | D8: ='長期'!D488 -> 137
A9: =IF('長期'!A487="","",'長期'!A487) -> 44771 | D9: ='長期'!D487 -> 140
A10: =IF('長期'!A486="","",'長期'!A486) -> 44774 | D10: ='長期'!D486 -> 143
A11: =IF('長期'!A485="","",'長期'!A485) -> 44775 | D11: ='長期'!D485 -> 143
A12: =IF('長期'!A484="","",'長期'!A484) -> 44776 | D12: ='長期'!D484 -> 143
A13: =IF('長期'!A483="","",'長期'!A483) -> 44777 | D13: ='長期'!D483 -> 145
A14: =IF('長期'!A482="","",'長期'!A482) -> 44778 | D14: ='長期'!D482 -> 144
A15: =IF('長期'!A481="","",'長期'!A481) -> 44781 | D15: ='長期'!D481 -> 131
A16: =IF('長期'!A480="","",'長期'!A480) -> 44782 | D16: ='長期'!D480 -> 129
A17: =IF('長期'!A479="","",'長期'!A479) -> 44783 | D17: ='長期'!D479 -> 128
A18: =IF('長期'!A478="","",'長期'!A478) -> 44785 | D18: ='長期'!D478 -> 128
A19: =IF('長期'!A477="","",'長期'!A477) -> 44788 | D19: ='長期'!D477 -> 130
A20: =IF('長期'!A476="","",'長期'!A476) -> 44789 | D20: ='長期'!D476 -> 131
A21: =IF('長期'!A475="","",'長期'!A475) -> 44790 | D21: ='長期'!D475 -> 132
A22: =IF('長期'!A474="","",'長期'!A474) -> 44791 | D22: ='長期'!D474 -> 128
A23: =IF('長期'!A473="","",'長期'!A473) -> 44792 | D23: ='長期'!D473 -> 130
A24: =IF('長期'!A472="","",'長期'!A472) -> 44795 | D24: ='長期'!D472 -> 135
A25: =IF('長期'!A471="","",'長期'!A471) -> 44796 | B25: =AVERAGE(D2:D25)+STDEV(D2:D25)*2 -> 148.86464 | C25: =AVERAGE(D2:D25)+STDEV(D2:D25) -> 142.57815 | D25: ='長期'!D471 -> 138 | E25: =AVERAGE(D2:D25)-STDEV(D2:D25) -> 130.00518 | F25: =AVERAGE(D2:D25)-STDEV(D2:D25)*2 -> 123.71869
A26: =IF('長期'!A470="","",'長期'!A470) -> 44797 | B26: =AVERAGE(D2:D26)+STDEV(D2:D26)*2 -> 148.68721 | C26: =AVERAGE(D2:D26)+STDEV(D2:D26) -> 142.5236 | D26: ='長期'!D470 -> 138 | E26: =AVERAGE(D2:D26)-STDEV(D2:D26) -> 130.1964 | F26: =AVERAGE(D2:D26)-STDEV(D2:D26)*2 -> 124.03279
A27: =IF('長期'!A469="","",'長期'!A469) -> 44798 | B27: =AVERAGE(D3:D27)+STDEV(D3:D27)*2 -> 148.87445 | C27: =AVERAGE(D3:D27)+STDEV(D3:D27) -> 142.81723 | D27: ='長期'!D469 -> 140 | E27: =AVERAGE(D3:D27)-STDEV(D3:D27) -> 130.70277 | F27: =AVERAGE(D3:D27)-STDEV(D3:D27)*2 -> 124.64555
A28: =IF('長期'!A468="","",'長期'!A468) -> 44799 | B28: =AVERAGE(D4:D28)+STDEV(D4:D28)*2 -> 148.09756 | C28: =AVERAGE(D4:D28)+STDEV(D4:D28) -> 142.30878 | D28: ='長期'!D468 -> 140 | E28: =AVERAGE(D4:D28)-STDEV(D4:D28) -> 130.73122 | F28: =AVERAGE(D4:D28)-STDEV(D4:D28)*2 -> 124.94244
A29: =IF('長期'!A467="","",'長期'!A467) -> 44802 | B29: =AVERAGE(D5:D29)+STDEV(D5:D29)*2 -> 147.85753 | C29: =AVERAGE(D5:D29)+STDEV(D5:D29) -> 142.14877 | D29: ='長期'!D467 -> 141 | E29: =AVERAGE(D5:D29)-STDEV(D5:D29) -> 130.73123 | F29: =AVERAGE(D5:D29)-STDEV(D5:D29)*2 -> 125.02247
A30: =IF('長期'!A466="","",'長期'!A466) -> 44803 | B30: =AVERAGE(D6:D30)+STDEV(D6:D30)*2 -> 147.92727 | C30: =AVERAGE(D6:D30)+STDEV(D6:D30) -> 142.20364 | D30: ='長期'!D466 -> 139 | E30: =AVERAGE(D6:D30)-STDEV(D6:D30) -> 130.75636 | F30: =AVERAGE(D6:D30)-STDEV(D6:D30)*2 -> 125.03273
A31: =IF('長期'!A465="","",'長期'!A465) -> 44804 | B31: =AVERAGE(D7:D31)+STDEV(D7:D31)*2 -> 148.03984 | C31: =AVERAGE(D7:D31)+STDEV(D7:D31) -> 142.27992 | D31: ='長期'!D465 -> 142 | E31: =AVERAGE(D7:D31)-STDEV(D7:D31) -> 130.76008 | F31: =AVERAGE(D7:D31)-STDEV(D7:D31)*2 -> 125.00016
A32: =IF('長期'!A464="","",'長期'!A464) -> 44805 | B32: =AVERAGE(D8:D32)+STDEV(D8:D32)*2 -> 148.10816 | C32: =AVERAGE(D8:D32)+STDEV(D8:D32) -> 142.33408 | D32: ='長期'!D464 -> 139 | E32: =AVERAGE(D8:D32)-STDEV(D8:D32) -> 130.78592 | F32: =AVERAGE(D8:D32)-STDEV(D8:D32)*2 -> 125.01184
A33: =IF('長期'!A463="","",'長期'!A463) -> 44806 | B33: =AVERAGE(D9:D33)+STDEV(D9:D33)*2 -> 148.04316 | C33: =AVERAGE(D9:D33)+STDEV(D9:D33) -> 142.26158 | D33: ='長期'!D463 -> 135 | E33: =AVERAGE(D9:D33)-STDEV(D9:D33) -> 130.69842 | F33: =AVERAGE(D9:D33)-STDEV(D9:D33)*2 -> 124.91684
A34: =IF('長期'!A462="","",'長期'!A462) -> 44809 | B34: =AVERAGE(D10:D34)+STDEV(D10:D34)*2 -> 147.79054 | C34: =AVERAGE(D10:D34)+STDEV(D10:D34) -> 142.05527 | D34: ='長期'!D462 -> 136 | E34: =AVERAGE(D10:D34)-STDEV(D10:D34) -> 130.58473 | F34: =AVERAGE(D10:D34)-STDEV(D10:D34)*2 -> 124.84946
A35: =IF('長期'!A461="","",'長期'!A461) -> 44810 | B35: =AVERAGE(D11:D35)+STDEV(D11:D35)*2 -> 147.16774 | C35: =AVERAGE(D11:D35)+STDEV(D11:D35) -> 141.60387 | D35: ='長期'!D461 -> 136 | E35: =AVERAGE(D11:D35)-STDEV(D11:D35) -> 130.47613 | F35: =AVERAGE(D11:D35)-STDEV(D11:D35)*2 -> 124.91226
A36: =IF('長期'!A460="","",'長期'!A460) -> 44811 | B36: =AVERAGE(D12:D36)+STDEV(D12:D36)*2 -> 146.4674 | C36: =AVERAGE(D12:D36)+STDEV(D12:D36) -> 141.0937 | D36: ='長期'!D460 -> 135 | E36: =AVERAGE(D12:D36)-STDEV(D12:D36) -> 130.3463 | F36: =AVERAGE(D12:D36)-STDEV(D12:D36)*2 -> 124.9726
A37: =IF('長期'!A459="","",'長期'!A459) -> 44812 | B37: =AVERAGE(D13:D37)+STDEV(D13:D37)*2 -> 145.7531 | C37: =AVERAGE(D13:D37)+STDEV(D13:D37) -> 140.59655 | D37: ='長期'!D459 -> 136 | E37: =AVERAGE(D13:D37)-STDEV(D13:D37) -> 130.28345 | F37: =AVERAGE(D13:D37)-STDEV(D13:D37)*2 -> 125.1269
A38: =IF('長期'!A458="","",'長期'!A458) -> 44813 | B38: =AVERAGE(D14:D38)+STDEV(D14:D38)*2 -> 144.8571 | C38: =AVERAGE(D14:D38)+STDEV(D14:D38) -> 139.76855 | D38: ='長期'!D458 -> 126 | E38: =AVERAGE(D14:D38)-STDEV(D14:D38) -> 129.59145 | F38: =AVERAGE(D14:D38)-STDEV(D14:D38)*2 -> 124.5029
A39: =IF('長期'!A457="","",'長期'!A457) -> 44816 | B39: =AVERAGE(D15:D39)+STDEV(D15:D39)*2 -> 143.68243 | C39: =AVERAGE(D15:D39)+STDEV(D15:D39) -> 138.90121 | D39: ='長期'!D457 -> 130 | E39: =AVERAGE(D15:D39)-STDEV(D15:D39) -> 129.33879 | F39: =AVERAGE(D15:D39)-STDEV(D15:D39)*2 -> 124.55757
A40: =IF('長期'!A456="","",'長期'!A456) -> 44817 | B40: =AVERAGE(D16:D40)+STDEV(D16:D40)*2 -> 143.70497 | C40: =AVERAGE(D16:D40)+STDEV(D16:D40) -> 138.89248 | D40: ='長期'!D456 -> 130 | E40: =AVERAGE(D16:D40)-STDEV(D16:D40) -> 129.26752 | F40: =AVERAGE(D16:D40)-STDEV(D16:D40)*2 -> 124.45503
...
